Workbook

Sheet README
A1: VYNE CEO Financial Operating Model
A3: VYNE Strategies — technology-enabled executive recruiting platform for financial advisors
A4: Founder & Chief Executive Officer: Mike Davies
A6: HOW TO USE
A7: 1. All inputs live on the Assumptions tab (blue cells). Every other tab calculates from it.
A8: 2. Switch scenarios with the yellow cell on Assumptions (1=Conservative, 2=Expected, 3=Aggressive). The entire model repopulates.
A9: 3. Color code: BLUE = input you can change | BLACK = formula | GREEN = link to another tab.
A11: TAB GUIDE
A12: Market — TAM / SAM / SOM and achieved market share
A13: Funnels — website inbound funnel, recruiter cold-call funnel, conversion & close rates, placement volume
A14: Revenue — placements by band, Annual Verified T12 Revenue Hired, tiered fees (8% / 10% / 12–14%), collections
A15: Recruiters — per-recruiter unit economics (1099 contractor model) and the recommended commission tier structure
... A31: This model contains no RBC data. All market figures are planning estimates pending cited third-party sources.

Sheet Assumptions
A1: VYNE Strategies — Master Assumptions (single input source)
A3: Active Scenario (1=Conservative, 2=Expected, 3=Aggressive): | D3: 2 | E3: =CHOOSE($D$3,"Conservative","Expected","Aggressive") -> Expected
A5: Assumption | B5: Conservative | C5: Expected | D5: Aggressive | E5: ACTIVE | F5: Notes
A6: MARKET
A7: Experienced advisor moves per year (>$500K T12) | B7: 8000 | C7: 9500 | D7: 11000 | E7: =CHOOSE($D$3,B7,C7,D7) -> 9500 | F7: Estimate; replace with cited industry data
A8: Avg verified T12 per market move ($mm) | B8: 1.2 | C8: 1.4 | D8: 1.6 | E8: =CHOOSE($D$3,B8,C8,D8) -> 1.4 | F8: $ millions
A9: Blended market recruiting fee (% of T12) | B9: 0.08 | C9: 0.085 | D9: 0.09 | E9: =CHOOSE($D$3,B9,C9,D9) -> 0.085
A10: SAM as % of TAM | B10: 0.4 | C10: 0.45 | D10: 0.5 | E10: =CHOOSE($D$3,B10,C10,D10) -> 0.45 | F10: Channels VYNE serves: wirehouse, regional, independent
A11: PLACEMENT FEES — VYNE fee as % of Verified T12
A12: Fee — Band A (<$5M T12) | B12: 0.08 | C12: 0.08 | D12: 0.08 | E12: =CHOOSE($D$3,B12,C12,D12) -> 0.08 | F12: Locked tier structure
A13: Fee — Band B ($5–10M T12) | B13: 0.1 | C13: 0.1 | D13: 0.1 | E13: =CHOOSE($D$3,B13,C13,D13) -> 0.1
A14: Fee — Band C (>$10M T12) | B14: 0.12 | C14: 0.12 | D14: 0.13 | E14: =CHOOSE($D$3,B14,C14,D14) -> 0.12 | F14: Contract range 12–14%
A15: Avg verified T12 — Band A ($mm) | B15: 1 | C15: 1.2 | D15: 1.4 | E15: =CHOOSE($D$3,B15,C15,D15) -> 1.2
A16: Avg verified T12 — Band B ($mm) | B16: 6 | C16: 6.5 | D16: 7 | E16: =CHOOSE($D$3,B16,C16,D16) -> 6.5
A17: Avg verified T12 — Band C ($mm) | B17: 12 | C17: 14 | D17: 16 | E17: =CHOOSE($D$3,B17,C17,D17) -> 14
A18: Placement mix — Band A | B18: 0.92 | C18: 0.9 | D18: 0.88 | E18: =CHOOSE($D$3,B18,C18,D18) -> 0.9 | F18: Mix must sum to 100%
A19: Placement mix — Band B | B19: 0.06 | C19: 0.08 | D19: 0.09 | E19: =CHOOSE($D$3,B19,C19,D19) -> 0.08
A20: Placement mix — Band C | B20: 0.02 | C20: 0.02 | D20: 0.03 | E20: =CHOOSE($D$3,B20,C20,D20) -> 0.02
A21: WEBSITE / INBOUND LEAD FUNNEL
A22: Monthly website visitors — Year 1 | B22: 300 | C22: 500 | D22: 800 | E22: =CHOOSE($D$3,B22,C22,D22) -> 500 | F22: AEO-driven inbound
A23: Monthly website visitors — Year 2 | B23: 900 | C23: 1500 | D23: 2400 | E23: =CHOOSE($D$3,B23,C23,D23) -> 1500 | F23: AEO-driven inbound
A24: Monthly website visitors — Year 3 | B24: 1800 | C24: 3000 | D24: 4800 | E24: =CHOOSE($D$3,B24,C24,D24) -> 3000 | F24: AEO-driven inbound
A25: Monthly website visitors — Year 4 | B25: 3000 | C25: 5000 | D25: 8000 | E25: =CHOOSE($D$3,B25,C25,D25) -> 5000 | F25: AEO-driven inbound
A26: Monthly website visitors — Year 5 | B26: 4200 | C26: 7000 | D26: 11000 | E26: =CHOOSE($D$3,B26,C26,D26) -> 7000 | F26: AEO-driven inbound
A27: Visitor → lead conversion | B27: 0.007 | C27: 0.01 | D27: 0.014 | E27: =CHOOSE($D$3,B27,C27,D27) -> 0.01
A28: Lead → qualified consultation | B28: 0.25 | C28: 0.3 | D28: 0.35 | E28: =CHOOSE($D$3,B28,C28,D28) -> 0.3
A29: Qualified → engaged advisor | B29: 0.25 | C29: 0.3 | D29: 0.35 | E29: =CHOOSE($D$3,B29,C29,D29) -> 0.3
A30: Engaged → placed (inbound close rate) | B30: 0.35 | C30: 0.4 | D30: 0.45 | E30: =CHOOSE($D$3,B30,C30,D30) -> 0.4
A31: RECRUITER COLD-CALL FUNNEL
A32: Dials per recruiter per day | B32: 60 | C32: 60 | D32: 60 | E32: =CHOOSE($D$3,B32,C32,D32) -> 60
A33: Working days per year | B33: 230 | C33: 230 | D33: 230 | E33: =CHOOSE($D$3,B33,C33,D33) -> 230
A34: Dial → live conversation | B34: 0.06 | C34: 0.08 | D34: 0.09 | E34: =CHOOSE($D$3,B34,C34,D34) -> 0.08
A35: Conversation → meeting | B35: 0.05 | C35: 0.06 | D35: 0.065 | E35: =CHOOSE($D$3,B35,C35,D35) -> 0.06
A36: Meeting → engaged advisor | B36: 0.2 | C36: 0.25 | D36: 0.28 | E36: =CHOOSE($D$3,B36,C36,D36) -> 0.25
A37: Engaged → placed (outbound close rate) | B37: 0.3 | C37: 0.35 | D37: 0.38 | E37: =CHOOSE($D$3,B37,C37,D37) -> 0.35
A38: New recruiter Year-1 productivity ramp | B38: 0.5 | C38: 0.5 | D38: 0.5 | E38: =CHOOSE($D$3,B38,C38,D38) -> 0.5
A39: TEAM & HIRING PLAN
A40: Recruiters on staff — Year 2 | B40: 1 | C40: 1 | D40: 2 | E40: =CHOOSE($D$3,B40,C40,D40) -> 1
A41: Recruiters on staff — Year 3 | B41: 1 | C41: 2 | D41: 4 | E41: =CHOOSE($D$3,B41,C41,D41) -> 2
A42: Recruiters on staff — Year 4 | B42: 2 | C42: 4 | D42: 6 | E42: =CHOOSE($D$3,B42,C42,D42) -> 4
...

Sheet Market
A1: TAM / SAM / SOM & Market Share Model
A3: TAM — total US advisor recruiting fee pool | B3: =Assumptions!$E$7*Assumptions!$E$8*1000000*Assumptions!$E$9 -> 1130500000 | D3: Moves × avg T12 × blended fee
A4: SAM — VYNE-serviceable channels | B4: =B3*Assumptions!$E$10 -> 508725000
A6: SOM — VYNE ACHIEVED SHARE (modeled)
B7: Year 1 | C7: Year 2 | D7: Year 3 | E7: Year 4 | F7: Year 5
A8: VYNE billed revenue | B8: =Revenue!B18 -> 1059520 | C8: =Revenue!C18 -> 2473016 | D8: =Revenue!D18 -> 4756488 | E8: =Revenue!E18 -> 7737936 | F8: =Revenue!F18 -> 11217840
A9: Share of SAM (revenue) | B9: =B8/$B$4 -> 0.0020826969 | C9: =C8/$B$4 -> 0.004861204 | D9: =D8/$B$4 -> 0.0093498216 | E9: =E8/$B$4 -> 0.01521045 | F9: =F8/$B$4 -> 0.022050892
A10: Placements / market moves (unit share) | B10: =Funnels!B23/Assumptions!$E$7 -> 0.00064842105 | C10: =Funnels!C23/Assumptions!$E$7 -> 0.0015134737 | D10: =Funnels!D23/Assumptions!$E$7 -> 0.0029109474 | E10: =Funnels!E23/Assumptions!$E$7 -> 0.0047355789 | F10: =Funnels!F23/Assumptions!$E$7 -> 0.0068652632

Sheet Funnels
A1: Lead Funnels & Placement Volume
B3: Year 1 | C3: Year 2 | D3: Year 3 | E3: Year 4 | F3: Year 5
A4: WEBSITE / INBOUND FUNNEL
A5: Monthly visitors | B5: =Assumptions!$E$22 -> 500 | C5: =Assumptions!$E$23 -> 1500 | D5: =Assumptions!$E$24 -> 3000 | E5: =Assumptions!$E$25 -> 5000 | F5: =Assumptions!$E$26 -> 7000
A6: Annual visitors | B6: =B5*12 -> 6000 | C6: =C5*12 -> 18000 | D6: =D5*12 -> 36000 | E6: =E5*12 -> 60000 | F6: =F5*12 -> 84000
A7: Leads (form fills) | B7: =B6*Assumptions!$E$27 -> 60 | C7: =C6*Assumptions!$E$27 -> 180 | D7: =D6*Assumptions!$E$27 -> 360 | E7: =E6*Assumptions!$E$27 -> 600 | F7: =F6*Assumptions!$E$27 -> 840
A8: Qualified consultations | B8: =B7*Assumptions!$E$28 -> 18 | C8: =C7*Assumptions!$E$28 -> 54 | D8: =D7*Assumptions!$E$28 -> 108 | E8: =E7*Assumptions!$E$28 -> 180 | F8: =F7*Assumptions!$E$28 -> 252
A9: Engaged advisors | B9: =B8*Assumptions!$E$29 -> 5.4 | C9: =C8*Assumptions!$E$29 -> 16.2 | D9: =D8*Assumptions!$E$29 -> 32.4 | E9: =E8*Assumptions!$E$29 -> 54 | F9: =F8*Assumptions!$E$29 -> 75.6
A10: Placements — inbound (VYNE-generated) | B10: =B9*Assumptions!$E$30 -> 2.16 | C10: =C9*Assumptions!$E$30 -> 6.48 | D10: =D9*Assumptions!$E$30 -> 12.96 | E10: =E9*Assumptions!$E$30 -> 21.6 | F10: =F9*Assumptions!$E$30 -> 30.24
A11: RECRUITER COLD-CALL FUNNEL
A12: Recruiters on staff (EOY) | B12: =0 -> 0 | C12: =Assumptions!$E$40 -> 1 | D12: =Assumptions!$E$41 -> 2 | E12: =Assumptions!$E$42 -> 4 | F12: =Assumptions!$E$43 -> 6
A13: Effective recruiter FTEs (ramp-adjusted) | B13: =0 -> 0 | C13: =B12+(C12-B12)*Assumptions!$E$38 -> 0.5 | D13: =C12+(D12-C12)*Assumptions!$E$38 -> 1.5 | E13: =D12+(E12-D12)*Assumptions!$E$38 -> 3 | F13: =E12+(F12-E12)*Assumptions!$E$38 -> 5
A14: Dials per recruiter per year | B14: =Assumptions!$E$32*Assumptions!$E$33 -> 13800 | C14: =Assumptions!$E$32*Assumptions!$E$33 -> 13800 | D14: =Assumptions!$E$32*Assumptions!$E$33 -> 13800 | E14: =Assumptions!$E$32*Assumptions!$E$33 -> 13800 | F14: =Assumptions!$E$32*Assumptions!$E$33 -> 13800
A15: Conversations per recruiter | B15: =B14*Assumptions!$E$34 -> 1104 | C15: =C14*Assumptions!$E$34 -> 1104 | D15: =D14*Assumptions!$E$34 -> 1104 | E15: =E14*Assumptions!$E$34 -> 1104 | F15: =F14*Assumptions!$E$34 -> 1104
A16: Meetings per recruiter | B16: =B15*Assumptions!$E$35 -> 66.24 | C16: =C15*Assumptions!$E$35 -> 66.24 | D16: =D15*Assumptions!$E$35 -> 66.24 | E16: =E15*Assumptions!$E$35 -> 66.24 | F16: =F15*Assumptions!$E$35 -> 66.24
A17: Engaged advisors per recruiter | B17: =B16*Assumptions!$E$36 -> 16.56 | C17: =C16*Assumptions!$E$36 -> 16.56 | D17: =D16*Assumptions!$E$36 -> 16.56 | E17: =E16*Assumptions!$E$36 -> 16.56 | F17: =F16*Assumptions!$E$36 -> 16.56
A18: Placements per recruiter (mature) | B18: =B17*Assumptions!$E$37 -> 5.796 | C18: =C17*Assumptions!$E$37 -> 5.796 | D18: =D17*Assumptions!$E$37 -> 5.796 | E18: =E17*Assumptions!$E$37 -> 5.796 | F18: =F17*Assumptions!$E$37 -> 5.796
A19: Placements — recruiter-sourced | B19: =B13*B18 -> 0 | C19: =C13*C18 -> 2.898 | D19: =D13*D18 -> 8.694 | E19: =E13*E18 -> 17.388 | F19: =F13*F18 -> 28.98
A20: FOUNDER NETWORK
A21: Placements — founder-led (no commission) | B21: =Assumptions!$E$44 -> 4 | C21: =Assumptions!$E$45 -> 5 | D21: =Assumptions!$E$46 -> 6 | E21: =Assumptions!$E$47 -> 6 | F21: =Assumptions!$E$48 -> 6
A22: TOTAL
A23: TOTAL PLACEMENTS | B23: =B10+B19+B21 -> 6.16 | C23: =C10+C19+C21 -> 14.378 | D23: =D10+D19+D21 -> 27.654 | E23: =E10+E19+E21 -> 44.988 | F23: =F10+F19+F21 -> 65.22
A24: Source mix — VYNE-generated | B24: =B10/B23 -> 0.35064935 | C24: =C10/C23 -> 0.45068855 | D24: =D10/D23 -> 0.4686483 | E24: =E10/E23 -> 0.48012803 | F24: =F10/F23 -> 0.46366145
A25: Source mix — recruiter-sourced | B25: =B19/B23 -> 0 | C25: =C19/C23 -> 0.20155794 | D25: =D19/D23 -> 0.3143849 | E25: =E19/E23 -> 0.38650307 | F25: =F19/F23 -> 0.44434223
A26: Source mix — founder-led | B26: =B21/B23 -> 0.64935065 | C26: =C21/C23 -> 0.34775351 | D26: =D21/D23 -> 0.2169668 | E26: =E21/E23 -> 0.1333689 | F26: =F21/F23 -> 0.09199632

Sheet Revenue
A1: Revenue Model — Fees on Annual Verified T12 Revenue Hired
B3: Year 1 | C3: Year 2 | D3: Year 3 | E3: Year 4 | F3: Year 5
A4: PLACEMENTS BY BAND
A5: Total placements | B5: =Funnels!B23 -> 6.16 | C5: =Funnels!C23 -> 14.378 | D5: =Funnels!D23 -> 27.654 | E5: =Funnels!E23 -> 44.988 | F5: =Funnels!F23 -> 65.22
A6: Band A placements (<$5M T12) | B6: =B5*Assumptions!$E$18 -> 5.544 | C6: =C5*Assumptions!$E$18 -> 12.9402 | D6: =D5*Assumptions!$E$18 -> 24.8886 | E6: =E5*Assumptions!$E$18 -> 40.4892 | F6: =F5*Assumptions!$E$18 -> 58.698
A7: Band B placements ($5–10M) | B7: =B5*Assumptions!$E$19 -> 0.4928 | C7: =C5*Assumptions!$E$19 -> 1.15024 | D7: =D5*Assumptions!$E$19 -> 2.21232 | E7: =E5*Assumptions!$E$19 -> 3.59904 | F7: =F5*Assumptions!$E$19 -> 5.2176
A8: Band C placements (>$10M) | B8: =B5*Assumptions!$E$20 -> 0.1232 | C8: =C5*Assumptions!$E$20 -> 0.28756 | D8: =D5*Assumptions!$E$20 -> 0.55308 | E8: =E5*Assumptions!$E$20 -> 0.89976 | F8: =F5*Assumptions!$E$20 -> 1.3044
A9: ANNUAL VERIFIED T12 REVENUE HIRED ($mm)
A10: Band A T12 hired | B10: =B6*Assumptions!$E$15 -> 6.6528 | C10: =C6*Assumptions!$E$15 -> 15.52824 | D10: =D6*Assumptions!$E$15 -> 29.86632 | E10: =E6*Assumptions!$E$15 -> 48.58704 | F10: =F6*Assumptions!$E$15 -> 70.4376
A11: Band B T12 hired | B11: =B7*Assumptions!$E$16 -> 3.2032 | C11: =C7*Assumptions!$E$16 -> 7.47656 | D11: =D7*Assumptions!$E$16 -> 14.38008 | E11: =E7*Assumptions!$E$16 -> 23.39376 | F11: =F7*Assumptions!$E$16 -> 33.9144
A12: Band C T12 hired | B12: =B8*Assumptions!$E$17 -> 1.7248 | C12: =C8*Assumptions!$E$17 -> 4.02584 | D12: =D8*Assumptions!$E$17 -> 7.74312 | E12: =E8*Assumptions!$E$17 -> 12.59664 | F12: =F8*Assumptions!$E$17 -> 18.2616
A13: TOTAL VERIFIED T12 HIRED ($mm) | B13: =SUM(B10:B12) -> 11.5808 | C13: =SUM(C10:C12) -> 27.03064 | D13: =SUM(D10:D12) -> 51.98952 | E13: =SUM(E10:E12) -> 84.57744 | F13: =SUM(F10:F12) -> 122.6136
A14: BILLED FEE REVENUE
A15: Band A fees @ 8% | B15: =B10*1000000*Assumptions!$E$12 -> 532224 | C15: =C10*1000000*Assumptions!$E$12 -> 1242259.2 | D15: =D10*1000000*Assumptions!$E$12 -> 2389305.6 | E15: =E10*1000000*Assumptions!$E$12 -> 3886963.2 | F15: =F10*1000000*Assumptions!$E$12 -> 5635008
A16: Band B fees @ 10% | B16: =B11*1000000*Assumptions!$E$13 -> 320320 | C16: =C11*1000000*Assumptions!$E$13 -> 747656 | D16: =D11*1000000*Assumptions!$E$13 -> 1438008 | E16: =E11*1000000*Assumptions!$E$13 -> 2339376 | F16: =F11*1000000*Assumptions!$E$13 -> 3391440
A17: Band C fees @ 12–14% | B17: =B12*1000000*Assumptions!$E$14 -> 206976 | C17: =C12*1000000*Assumptions!$E$14 -> 483100.8 | D17: =D12*1000000*Assumptions!$E$14 -> 929174.4 | E17: =E12*1000000*Assumptions!$E$14 -> 1511596.8 | F17: =F12*1000000*Assumptions!$E$14 -> 2191392
A18: TOTAL BILLED REVENUE | B18: =SUM(B15:B17) -> 1059520 | C18: =SUM(C15:C17) -> 2473016 | D18: =SUM(D15:D17) -> 4756488 | E18: =SUM(E15:E17) -> 7737936 | F18: =SUM(F15:F17) -> 11217840
A19: Average VYNE fee per placement | B19: =B18/B5 -> 172000 | C19: =C18/C5 -> 172000 | D19: =D18/D5 -> 172000 | E19: =E18/E5 -> 172000 | F19: =F18/F5 -> 172000
A20: Blended fee rate (% of T12) | B20: =B18/(B13*1000000) -> 0.091489362 | C20: =C18/(C13*1000000) -> 0.091489362 | D20: =D18/(D13*1000000) -> 0.091489362 | E20: =E18/(E13*1000000) -> 0.091489362 | F20: =F18/(F13*1000000) -> 0.091489362
A21: REVENUE BY LEAD SOURCE
A22: VYNE-generated (inbound) | B22: =B18*Funnels!B24 -> 371520 | C22: =C18*Funnels!C24 -> 1114560 | D22: =D18*Funnels!D24 -> 2229120 | E22: =E18*Funnels!E24 -> 3715200 | F22: =F18*Funnels!F24 -> 5201280
A23: Recruiter-sourced | B23: =B18*Funnels!B25 -> 0 | C23: =C18*Funnels!C25 -> 498456 | D23: =D18*Funnels!D25 -> 1495368 | E23: =E18*Funnels!E25 -> 2990736 | F23: =F18*Funnels!F25 -> 4984560
A24: Founder-led | B24: =B18*Funnels!B26 -> 688000 | C24: =C18*Funnels!C26 -> 860000 | D24: =D18*Funnels!D26 -> 1032000 | E24: =E18*Funnels!E26 -> 1032000 | F24: =F18*Funnels!F26 -> 1032000
A25: CASH COLLECTIONS
A26: Cash collections | B26: =B18*Assumptions!$E$68 -> 900592 | C26: =C18*Assumptions!$E$68+B18*(1-Assumptions!$E$68) -> 2260991.6 | D26: =D18*Assumptions!$E$68+C18*(1-Assumptions!$E$68) -> 4413967.2 | E26: =E18*Assumptions!$E$68+D18*(1-Assumptions!$E$68) -> 7290718.8 | F26: =F18*Assumptions!$E$68+E18*(1-Assumptions!$E$68) -> 10695854

Sheet Recruiters
A1: Recruiter Economics & Commission Structure (Recommendation)
A3: UNIT ECONOMICS — MATURE RECRUITER (Year 3 basis)
A4: Placements per recruiter per year | B4: =Funnels!D18 -> 5.796
A5: Average VYNE fee per placement | B5: =Revenue!D19 -> 172000
A6: Fee revenue generated per recruiter | B6: =B4*B5 -> 996912
A7: Commission earned (recruiter-sourced blend) | B7: =B6*Assumptions!$E$57 -> 418703.04
A8: Base compensation (1099 - none; draw is recoverable) | B8: =0 -> 0
A9: Recruiter total cash comp (all commission) | B9: =B8+B7 -> 418703.04
A10: Cost to VYNE (commission; draw recoverable) | B10: =B7 -> 418703.04
A11: Net contribution per recruiter | B11: =B6-B10 -> 578208.96
A12: Contribution margin on recruiter revenue | B12: =B11/B6 -> 0.58
A14: COMMISSION TIER RECOMMENDATION — pending Sensitivity validation
A15: Tier — Annual Verified T12 Revenue Hired | B15: Recruiter-sourced lead | C15: VYNE-generated lead | D15: Notes
A16: Tier 1: first $10M T12 hired | B16: 0.4 | C16: 0.25 | D16: Applies from $0 each Commission Year
A17: Tier 2: $10M – $25M T12 hired | B17: 0.45 | C17: 0.3 | D17: Marginal rate on fees from T12 in this band
A18: Tier 3: above $25M T12 hired | B18: 0.5 | C18: 0.35 | D18: Marginal rate; rewards elite producers
A20: • Commission Year = January 1 – December 31. Tiers reset to $0 every January 1.
A21: • Percentages apply ONLY to the actual VYNE Strategies fee collected — never to advisor T12 revenue.
A22: • Tier credit is based on Annual Verified T12 Revenue Hired: T12 verified by the hiring firm for advisors whose official hire date falls in the Commission Year.
A23: • VYNE-generated leads pay ~15 points less: VYNE built the platform, brand, marketing, AI, and inbound engine.
A24: • Commissions are paid only when VYNE collects; subject to clawback if the hiring firm claws back the fee.
A25: • Recruiters are independent contractors (1099-NEC). No base salary; a recoverable draw ($4,000/mo, months 1-6) is available and recouped from commission runs. Contractors bear self-employment taxes and their own business expenses.
A26: • DO NOT finalize in agreements until the Sensitivity tab confirms affordability at target margins and counsel approves the Independent Recruiter Agreement.

Sheet Hiring & Expenses
A1: Hiring Plan & Operating Expense Model
B3: Year 1 | C3: Year 2 | D3: Year 3 | E3: Year 4 | F3: Year 5
A4: HEADCOUNT
A5: Founder / CEO | B5: =1 -> 1 | C5: =1 -> 1 | D5: =1 -> 1 | E5: =1 -> 1 | F5: =1 -> 1
A6: Recruiters (1099 contractors) | B6: =Funnels!B12 -> 0 | C6: =Funnels!C12 -> 1 | D6: =Funnels!D12 -> 2 | E6: =Funnels!E12 -> 4 | F6: =Funnels!F12 -> 6
A7: Operations manager | B7: =IF(1>=Assumptions!$E$53,1,0) -> 0 | C7: =IF(2>=Assumptions!$E$53,1,0) -> 0 | D7: =IF(3>=Assumptions!$E$53,1,0) -> 1 | E7: =IF(4>=Assumptions!$E$53,1,0) -> 1 | F7: =IF(5>=Assumptions!$E$53,1,0) -> 1
A8: Total headcount | B8: =SUM(B5:B7) -> 1 | C8: =SUM(C5:C7) -> 2 | D8: =SUM(D5:D7) -> 4 | E8: =SUM(E5:E7) -> 6 | F8: =SUM(F5:F7) -> 8
A9: BASE COMPENSATION (excl. commissions)
A10: Founder salary | B10: =Assumptions!$E$49*(1+Assumptions!$E$50)^0 -> 96000 | C10: =Assumptions!$E$49*(1+Assumptions!$E$50)^1 -> 105600 | D10: =Assumptions!$E$49*(1+Assumptions!$E$50)^2 -> 116160 | E10: =Assumptions!$E$49*(1+Assumptions!$E$50)^3 -> 127776 | F10: =Assumptions!$E$49*(1+Assumptions!$E$50)^4 -> 140553.6
A11: Recruiter draw provision (1099, unrecovered) | B11: =B6*Assumptions!$E$52 -> 0 | C11: =MAX(0,C6-B6)*Assumptions!$E$52 -> 12000 | D11: =MAX(0,D6-C6)*Assumptions!$E$52 -> 12000 | E11: =MAX(0,E6-D6)*Assumptions!$E$52 -> 24000 | F11: =MAX(0,F6-E6)*Assumptions!$E$52 -> 24000
A12: Ops manager salary | B12: =IF(1>=Assumptions!$E$53,Assumptions!$E$54*(1+Assumptions!$E$50)^(1-Assumptions!$E$53),0) -> 0 | C12: =IF(2>=Assumptions!$E$53,Assumptions!$E$54*(1+Assumptions!$E$50)^(2-Assumptions!$E$53),0) -> 0 | D12: =IF(3>=Assumptions!$E$53,Assumptions!$E$54*(1+Assumptions!$E$50)^(3-Assumptions!$E$53),0) -> 75000 | E12: =IF(4>=Assumptions!$E$53,Assumptions!$E$54*(1+Assumptions!$E$50)^(4-Assumptions!$E$53),0) -> 82500 | F12: =IF(5>=Assumptions!$E$53,Assumptions!$E$54*(1+Assumptions!$E$50)^(5-Assumptions!$E$53),0) -> 90750
A13: W-2 wages (founder + ops) | B13: =B10+B12 -> 96000 | C13: =C10+C12 -> 105600 | D13: =D10+D12 -> 191160 | E13: =E10+E12 -> 210276 | F13: =F10+F12 -> 231303.6
A14: People cost (W-2 loaded + 1099 draw provision) | B14: =B13*(1+Assumptions!$E$55)+B11 -> 110400 | C14: =C13*(1+Assumptions!$E$55)+C11 -> 133440 | D14: =D13*(1+Assumptions!$E$55)+D11 -> 231834 | E14: =E13*(1+Assumptions!$E$55)+E11 -> 265817.4 | F14: =F13*(1+Assumptions!$E$55)+F11 -> 289999.14
A15: OPERATING EXPENSES
A16: AI budget (Claude API, agents, tools) | B16: =Assumptions!$E$60*(1+Assumptions!$E$66)^0 -> 18000 | C16: =Assumptions!$E$60*(1+Assumptions!$E$66)^1 -> 20700 | D16: =Assumptions!$E$60*(1+Assumptions!$E$66)^2 -> 23805 | E16: =Assumptions!$E$60*(1+Assumptions!$E$66)^3 -> 27375.75 | F16: =Assumptions!$E$60*(1+Assumptions!$E$66)^4 -> 31482.112
A17: Marketing budget | B17: =Assumptions!$E$61*(1+Assumptions!$E$66)^0 -> 36000 | C17: =Assumptions!$E$61*(1+Assumptions!$E$66)^1 -> 41400 | D17: =Assumptions!$E$61*(1+Assumptions!$E$66)^2 -> 47610 | E17: =Assumptions!$E$61*(1+Assumptions!$E$66)^3 -> 54751.5 | F17: =Assumptions!$E$61*(1+Assumptions!$E$66)^4 -> 62964.225
A18: Travel & business development | B18: =Assumptions!$E$62*(1+Assumptions!$E$66)^0 -> 24000 | C18: =Assumptions!$E$62*(1+Assumptions!$E$66)^1 -> 27600 | D18: =Assumptions!$E$62*(1+Assumptions!$E$66)^2 -> 31740 | E18: =Assumptions!$E$62*(1+Assumptions!$E$66)^3 -> 36501 | F18: =Assumptions!$E$62*(1+Assumptions!$E$66)^4 -> 41976.15
A19: Legal / accounting / insurance | B19: =Assumptions!$E$63*(1+Assumptions!$E$66)^0 -> 30000 | C19: =Assumptions!$E$63*(1+Assumptions!$E$66)^1 -> 34500 | D19: =Assumptions!$E$63*(1+Assumptions!$E$66)^2 -> 39675 | E19: =Assumptions!$E$63*(1+Assumptions!$E$66)^3 -> 45626.25 | F19: =Assumptions!$E$63*(1+Assumptions!$E$66)^4 -> 52470.188
A20: CRM / software / email / computers | B20: =Assumptions!$E$64*(1+Assumptions!$E$66)^0 -> 15000 | C20: =Assumptions!$E$64*(1+Assumptions!$E$66)^1 -> 17250 | D20: =Assumptions!$E$64*(1+Assumptions!$E$66)^2 -> 19837.5 | E20: =Assumptions!$E$64*(1+Assumptions!$E$66)^3 -> 22813.125 | F20: =Assumptions!$E$64*(1+Assumptions!$E$66)^4 -> 26235.094
A21: Office & miscellaneous | B21: =Assumptions!$E$65*(1+Assumptions!$E$66)^0 -> 6000 | C21: =Assumptions!$E$65*(1+Assumptions!$E$66)^1 -> 6900 | D21: =Assumptions!$E$65*(1+Assumptions!$E$66)^2 -> 7935 | E21: =Assumptions!$E$65*(1+Assumptions!$E$66)^3 -> 9125.25 | F21: =Assumptions!$E$65*(1+Assumptions!$E$66)^4 -> 10494.038
A22: Total operating expenses | B22: =SUM(B16:B21) -> 129000 | C22: =SUM(C16:C21) -> 148350 | D22: =SUM(D16:D21) -> 170602.5 | E22: =SUM(E16:E21) -> 196192.88 | F22: =SUM(F16:F21) -> 225621.81
A23: TOTAL FIXED COST BASE
A24: Payroll + opex (before commissions) | B24: =B14+B22 -> 239400 | C24: =C14+C22 -> 281790 | D24: =D14+D22 -> 402436.5 | E24: =E14+E22 -> 462010.28 | F24: =F14+F22 -> 515620.95

Sheet Startup Budget
A1: One-Time Startup Budget (pre-launch / Month 0)
A3: Item | B3: Amount | C3: Notes
A4: Entity formation, attorney review (OBA/non-solicit), contracts | B4: 12000 | C4: Gated on attorney sign-off
A5: Brand, website, domains (largely built) | B5: 4000
A6: Equipment (computer, phone, peripherals) | B6: 4000 | C6: Personal devices only during stealth
A7: Insurance deposits (E&O, general liability) | B7: 3000
A8: Initial marketing & content launch | B8: 5000
A9: Working capital buffer | B9: 15000
A10: TOTAL STARTUP COSTS | B10: =SUM(B4:B9) -> 43000
A12: Founder capital contribution | B12: =Assumptions!$E$72 -> 100000
A13: Opening operating cash (Day 1) | B13: =B12-B10 -> 57000

Sheet P&L
A1: 5-Year P&L, Break-Even & Margin Targets
B3: Year 1 | C3: Year 2 | D3: Year 3 | E3: Year 4 | F3: Year 5
A4: REVENUE
A5: Billed fee revenue | B5: =Revenue!B18 -> 1059520 | C5: =Revenue!C18 -> 2473016 | D5: =Revenue!D18 -> 4756488 | E5: =Revenue!E18 -> 7737936 | F5: =Revenue!F18 -> 11217840
A6: COMMISSION EXPENSE (% of VYNE fee, by lead source)
A7: On VYNE-generated placements | B7: =Revenue!B22*Assumptions!$E$58 -> 100310.4 | C7: =Revenue!C22*Assumptions!$E$58 -> 300931.2 | D7: =Revenue!D22*Assumptions!$E$58 -> 601862.4 | E7: =Revenue!E22*Assumptions!$E$58 -> 1003104 | F7: =Revenue!F22*Assumptions!$E$58 -> 1404345.6
A8: On recruiter-sourced placements | B8: =Revenue!B23*Assumptions!$E$57 -> 0 | C8: =Revenue!C23*Assumptions!$E$57 -> 209351.52 | D8: =Revenue!D23*Assumptions!$E$57 -> 628054.56 | E8: =Revenue!E23*Assumptions!$E$57 -> 1256109.1 | F8: =Revenue!F23*Assumptions!$E$57 -> 2093515.2
A9: Total commissions | B9: =B7+B8 -> 100310.4 | C9: =C7+C8 -> 510282.72 | D9: =D7+D8 -> 1229917 | E9: =E7+E8 -> 2259213.1 | F9: =F7+F8 -> 3497860.8
A10: Blended commission (% of revenue) | B10: =B9/B5 -> 0.094675325 | C10: =C9/C5 -> 0.20634024 | D10: =D9/D5 -> 0.2585767 | E10: =E9/E5 -> 0.29196586 | F10: =F9/F5 -> 0.31181233
A11: GROSS PROFIT
A12: Gross profit | B12: =B5-B9 -> 959209.6 | C12: =C5-C9 -> 1962733.3 | D12: =D5-D9 -> 3526571 | E12: =E5-E9 -> 5478722.9 | F12: =F5-F9 -> 7719979.2
A13: Gross margin | B13: =B12/B5 -> 0.90532468 | C13: =C12/C5 -> 0.79365976 | D13: =D12/D5 -> 0.7414233 | E13: =E12/E5 -> 0.70803414 | F13: =F12/F5 -> 0.68818767
A14: OPERATING COSTS
A15: People cost (W-2 loaded + draw prov.) | B15: ='Hiring & Expenses'!B14 -> 110400 | C15: ='Hiring & Expenses'!C14 -> 133440 | D15: ='Hiring & Expenses'!D14 -> 231834 | E15: ='Hiring & Expenses'!E14 -> 265817.4 | F15: ='Hiring & Expenses'!F14 -> 289999.14
A16: Operating expenses | B16: ='Hiring & Expenses'!B22 -> 129000 | C16: ='Hiring & Expenses'!C22 -> 148350 | D16: ='Hiring & Expenses'!D22 -> 170602.5 | E16: ='Hiring & Expenses'!E22 -> 196192.88 | F16: ='Hiring & Expenses'!F22 -> 225621.81
A17: Total fixed costs | B17: =B15+B16 -> 239400 | C17: =C15+C16 -> 281790 | D17: =D15+D16 -> 402436.5 | E17: =E15+E16 -> 462010.28 | F17: =F15+F16 -> 515620.95
A18: PROFITABILITY
A19: EBITDA (pre-founder distributions) | B19: =B12-B17 -> 719809.6 | C19: =C12-C17 -> 1680943.3 | D19: =D12-D17 -> 3124134.5 | E19: =E12-E17 -> 5016712.6 | F19: =F12-F17 -> 7204358.3
A20: EBITDA margin | B20: =B19/B5 -> 0.6793733 | C20: =C19/C5 -> 0.67971387 | D20: =D19/D5 -> 0.65681539 | E20: =E19/E5 -> 0.64832697 | F20: =F19/F5 -> 0.6422233
A21: BREAK-EVEN ANALYSIS
A22: Contribution per placement | B22: =Revenue!B19*(1-B10) -> 155715.84 | C22: =Revenue!C19*(1-C10) -> 136509.48 | D22: =Revenue!D19*(1-D10) -> 127524.81 | E22: =Revenue!E19*(1-E10) -> 121781.87 | F22: =Revenue!F19*(1-F10) -> 118368.28
A23: Break-even placements per year | B23: =B17/B22 -> 1.5374158 | C23: =C17/C22 -> 2.0642523 | D23: =D17/D22 -> 3.1557507 | E23: =E17/E22 -> 3.7937524 | F23: =F17/F22 -> 4.3560737
A24: Actual placements | B24: =Funnels!B23 -> 6.16 | C24: =Funnels!C23 -> 14.378 | D24: =Funnels!D23 -> 27.654 | E24: =Funnels!E23 -> 44.988 | F24: =Funnels!F23 -> 65.22
A25: Cushion (placements above break-even) | B25: =B24-B23 -> 4.6225842 | C25: =C24-C23 -> 12.313748 | D25: =D24-D23 -> 24.498249 | E25: =E24-E23 -> 41.194248 | F25: =F24-F23 -> 60.863926
A26: Break-even revenue | B26: =B23*Revenue!B19 -> 264435.52 | C26: =C23*Revenue!C19 -> 355051.39 | D26: =D23*Revenue!D19 -> 542789.12 | E26: =E23*Revenue!E19 -> 652525.42 | F26: =F23*Revenue!F19 -> 749244.67
A27: OPERATING MARGIN TARGETS
A28: Target EBITDA margin | B28: 0.15 | C28: 0.25 | D28: 0.3 | E28: 0.32 | F28: 0.35
A29: Target met? | B29: =IF(B20>=B28,"YES","NO") -> YES | C29: =IF(C20>=C28,"YES","NO") -> YES | D29: =IF(D20>=D28,"YES","NO") -> YES | E29: =IF(E20>=E28,"YES","NO") -> YES | F29: =IF(F20>=F28,"YES","NO") -> YES

Sheet Cash Flow
A1: Cash Flow — Annual (5-Year) & Monthly (Year 1)
B3: Year 1 | C3: Year 2 | D3: Year 3 | E3: Year 4 | F3: Year 5
A4: ANNUAL CASH FLOW
A5: Opening cash | B5: ='Startup Budget'!B13 -> 57000 | C5: =B12 -> 542868.96 | D5: =C12 -> 1919497 | E5: =D12 -> 4574381.1 | F5: =E12 -> 8986773.5
A6: Cash collections | B6: =Revenue!B26 -> 900592 | C6: =Revenue!C26 -> 2260991.6 | D6: =Revenue!D26 -> 4413967.2 | E6: =Revenue!E26 -> 7290718.8 | F6: =Revenue!F26 -> 10695854
A7: Commissions paid (on collected fees) | B7: =-B6*'P&L'!B10 -> -85263.84 | C7: =-C6*'P&L'!C10 -> -466533.55 | D7: =-D6*'P&L'!D10 -> -1141349.1 | E7: =-E6*'P&L'!E10 -> -2128641 | F7: =-F6*'P&L'!F10 -> -3335099.3
A8: Payroll & operating costs | B8: =-'P&L'!B17 -> -239400 | C8: =-'P&L'!C17 -> -281790 | D8: =-'P&L'!D17 -> -402436.5 | E8: =-'P&L'!E17 -> -462010.28 | F8: =-'P&L'!F17 -> -515620.95
A9: Clawback reserve funded | B9: =-B6*Assumptions!$E$69 -> -90059.2 | C9: =-C6*Assumptions!$E$69 -> -226099.16 | D9: =-D6*Assumptions!$E$69 -> -441396.72 | E9: =-E6*Assumptions!$E$69 -> -729071.88 | F9: =-F6*Assumptions!$E$69 -> -1069585.4
A10: Prior-year clawback reserve released | B10: =0 -> 0 | C10: =-B9 -> 90059.2 | D10: =-C9 -> 226099.16 | E10: =-D9 -> 441396.72 | F10: =-E9 -> 729071.88
A11: Net cash flow | B11: =SUM(B6:B10) -> 485868.96 | C11: =SUM(C6:C10) -> 1376628.1 | D11: =SUM(D6:D10) -> 2654884.1 | E11: =SUM(E6:E10) -> 4412392.4 | F11: =SUM(F6:F10) -> 6504620.6
A12: Ending cash (pre-distribution) | B12: =B5+B11 -> 542868.96 | C12: =C5+C11 -> 1919497 | D12: =D5+D11 -> 4574381.1 | E12: =E5+E11 -> 8986773.5 | F12: =F5+F11 -> 15491394
A13: Clawback reserve balance | B13: =-B9 -> 90059.2 | C13: =-C9 -> 226099.16 | D13: =-D9 -> 441396.72 | E13: =-E9 -> 729071.88 | F13: =-F9 -> 1069585.4
A14: Cash reserve target (6 mo fixed costs) | B14: ='P&L'!B17*Assumptions!$E$70/12 -> 119700 | C14: ='P&L'!C17*Assumptions!$E$70/12 -> 140895 | D14: ='P&L'!D17*Assumptions!$E$70/12 -> 201218.25 | E14: ='P&L'!E17*Assumptions!$E$70/12 -> 231005.14 | F14: ='P&L'!F17*Assumptions!$E$70/12 -> 257810.47
A15: Cash above reserve target | B15: =B12-B14 -> 423168.96 | C15: =C12-C14 -> 1778602 | D15: =D12-D14 -> 4373162.9 | E15: =E12-E14 -> 8755768.4 | F15: =F12-F14 -> 15233584
A16: Note: founder distributions are modeled on the Founder & Capital tab and are made only from cash above the reserve target.
A18: MONTHLY CASH FLOW — YEAR 1
A19: Month | B19: M1 | C19: M2 | D19: M3 | E19: M4 | F19: M5 | G19: M6 | H19: M7 | I19: M8 | J19: M9 | K19: M10 | L19: M11 | M19: M12
A20: Billing weight (% of Year 1) | B20: 0.02 | C20: 0.03 | D20: 0.04 | E20: 0.06 | F20: 0.08 | G20: 0.09 | H20: 0.1 | I20: 0.11 | J20: 0.11 | K20: 0.12 | L20: 0.12 | M20: 0.12
A21: Billed revenue | B21: ='P&L'!$B$5*B20 -> 21190.4 | C21: ='P&L'!$B$5*C20 -> 31785.6 | D21: ='P&L'!$B$5*D20 -> 42380.8 | E21: ='P&L'!$B$5*E20 -> 63571.2 | F21: ='P&L'!$B$5*F20 -> 84761.6 | G21: ='P&L'!$B$5*G20 -> 95356.8 | H21: ='P&L'!$B$5*H20 -> 105952 | I21: ='P&L'!$B$5*I20 -> 116547.2 | ... M21: ='P&L'!$B$5*M20 -> 127142.4
A22: Collections (60-day lag) | B22: =0 -> 0 | C22: =0 -> 0 | D22: =B21 -> 21190.4 | E22: =C21 -> 31785.6 | F22: =D21 -> 42380.8 | G22: =E21 -> 63571.2 | H22: =F21 -> 84761.6 | I22: =G21 -> 95356.8 | J22: =H21 -> 105952 | K22: =I21 -> 116547.2 | ... M22: =K21 -> 127142.4
A23: Commissions paid | B23: =-B22*'P&L'!$B$10 -> 0 | C23: =-C22*'P&L'!$B$10 -> 0 | D23: =-D22*'P&L'!$B$10 -> -2006.208 | E23: =-E22*'P&L'!$B$10 -> -3009.312 | F23: =-F22*'P&L'!$B$10 -> -4012.416 | G23: =-G22*'P&L'!$B$10 -> -6018.624 | H23: =-H22*'P&L'!$B$10 -> -8024.832 | I23: =-I22*'P&L'!$B$10 -> -9027.936 | ... M23: =-M22*'P&L'!$B$10 -> -12037.248
A24: Clawback reserve funded | B24: =-B22*Assumptions!$E$69 -> 0 | C24: =-C22*Assumptions!$E$69 -> 0 | D24: =-D22*Assumptions!$E$69 -> -2119.04 | E24: =-E22*Assumptions!$E$69 -> -3178.56 | F24: =-F22*Assumptions!$E$69 -> -4238.08 | G24: =-G22*Assumptions!$E$69 -> -6357.12 | H24: =-H22*Assumptions!$E$69 -> -8476.16 | I24: =-I22*Assumptions!$E$69 -> -9535.68 | ... M24: =-M22*Assumptions!$E$69 -> -12714.24
A25: Payroll & opex | B25: =-'P&L'!$B$17/12 -> -19950 | C25: =-'P&L'!$B$17/12 -> -19950 | D25: =-'P&L'!$B$17/12 -> -19950 | E25: =-'P&L'!$B$17/12 -> -19950 | F25: =-'P&L'!$B$17/12 -> -19950 | G25: =-'P&L'!$B$17/12 -> -19950 | H25: =-'P&L'!$B$17/12 -> -19950 | I25: =-'P&L'!$B$17/12 -> -19950 | ... M25: =-'P&L'!$B$17/12 -> -19950
A26: Net cash flow | B26: =SUM(B22:B25) -> -19950 | C26: =SUM(C22:C25) -> -19950 | D26: =SUM(D22:D25) -> -2884.848 | E26: =SUM(E22:E25) -> 5647.728 | F26: =SUM(F22:F25) -> 14180.304 | G26: =SUM(G22:G25) -> 31245.456 | H26: =SUM(H22:H25) -> 48310.608 | I26: =SUM(I22:I25) -> 56843.184 | ... M26: =SUM(M22:M25) -> 82440.912
A27: Ending cash | B27: ='Startup Budget'!$B$13+B26 -> 37050 | C27: =B27+C26 -> 17100 | D27: =C27+D26 -> 14215.152 | E27: =D27+E26 -> 19862.88 | F27: =E27+F26 -> 34043.184 | G27: =F27+G26 -> 65288.64 | H27: =G27+H26 -> 113599.25 | I27: =H27+I26 -> 170442.43 | J27: =I27+J26 -> 235818.19 | ... M27: =L27+M26 -> 466075.78
A28: PEAK CASH NEED (lowest monthly balance) | B28: =MIN(B27:M27) -> 14215.152

Sheet Sensitivity
A1: Commission Sensitivity — Year 3 EBITDA Margin
A3: Rows: recruiter-sourced commission % | Columns: placement volume vs. plan (Year 3). VYNE-lead payout held at Assumptions value.
A5: Comm % \ Volume | B5: 0.7 | C5: 0.85 | D5: 1 | E5: 1.15 | F5: 1.3
A6: 0.35 | B6: =(('P&L'!$D$5*B$5)-(('P&L'!$D$5*B$5)*(Funnels!$D$25*$A6+Funnels!$D$24*Assumptions!$E$58))-'P&L'!$D$17)/('P&L'!$D$5*B$5) -> 0.6425618 | C6: =(('P&L'!$D$5*C$5)-(('P&L'!$D$5*C$5)*(Funnels!$D$25*$A6+Funnels!$D$24*Assumptions!$E$58))-'P&L'!$D$17)/('P&L'!$D$5*C$5) -> 0.66389153 | D6: =(('P&L'!$D$5*D$5)-(('P&L'!$D$5*D$5)*(Funnels!$D$25*$A6+Funnels!$D$24*Assumptions!$E$58))-'P&L'!$D$17)/('P&L'!$D$5*D$5) -> 0.67882234 | E6: =(('P&L'!$D$5*E$5)-(('P&L'!$D$5*E$5)*(Funnels!$D$25*$A6+Funnels!$D$24*Assumptions!$E$58))-'P&L'!$D$17)/('P&L'!$D$5*E$5) -> 0.68985815 | F6: =(('P&L'!$D$5*F$5)-(('P&L'!$D$5*F$5)*(Funnels!$D$25*$A6+Funnels!$D$24*Assumptions!$E$58))-'P&L'!$D$17)/('P&L'!$D$5*F$5) -> 0.69834724
A7: 0.4 | B7: =(('P&L'!$D$5*B$5)-(('P&L'!$D$5*B$5)*(Funnels!$D$25*$A7+Funnels!$D$24*Assumptions!$E$58))-'P&L'!$D$17)/('P&L'!$D$5*B$5) -> 0.62684256 | C7: =(('P&L'!$D$5*C$5)-(('P&L'!$D$5*C$5)*(Funnels!$D$25*$A7+Funnels!$D$24*Assumptions!$E$58))-'P&L'!$D$17)/('P&L'!$D$5*C$5) -> 0.64817228 | D7: =(('P&L'!$D$5*D$5)-(('P&L'!$D$5*D$5)*(Funnels!$D$25*$A7+Funnels!$D$24*Assumptions!$E$58))-'P&L'!$D$17)/('P&L'!$D$5*D$5) -> 0.66310309 | E7: =(('P&L'!$D$5*E$5)-(('P&L'!$D$5*E$5)*(Funnels!$D$25*$A7+Funnels!$D$24*Assumptions!$E$58))-'P&L'!$D$17)/('P&L'!$D$5*E$5) -> 0.67413891 | F7: =(('P&L'!$D$5*F$5)-(('P&L'!$D$5*F$5)*(Funnels!$D$25*$A7+Funnels!$D$24*Assumptions!$E$58))-'P&L'!$D$17)/('P&L'!$D$5*F$5) -> 0.68262799
A8: 0.42 | B8: =(('P&L'!$D$5*B$5)-(('P&L'!$D$5*B$5)*(Funnels!$D$25*$A8+Funnels!$D$24*Assumptions!$E$58))-'P&L'!$D$17)/('P&L'!$D$5*B$5) -> 0.62055486 | C8: =(('P&L'!$D$5*C$5)-(('P&L'!$D$5*C$5)*(Funnels!$D$25*$A8+Funnels!$D$24*Assumptions!$E$58))-'P&L'!$D$17)/('P&L'!$D$5*C$5) -> 0.64188459 | D8: =(('P&L'!$D$5*D$5)-(('P&L'!$D$5*D$5)*(Funnels!$D$25*$A8+Funnels!$D$24*Assumptions!$E$58))-'P&L'!$D$17)/('P&L'!$D$5*D$5) -> 0.65681539 | E8: =(('P&L'!$D$5*E$5)-(('P&L'!$D$5*E$5)*(Funnels!$D$25*$A8+Funnels!$D$24*Assumptions!$E$58))-'P&L'!$D$17)/('P&L'!$D$5*E$5) -> 0.66785121 | F8: =(('P&L'!$D$5*F$5)-(('P&L'!$D$5*F$5)*(Funnels!$D$25*$A8+Funnels!$D$24*Assumptions!$E$58))-'P&L'!$D$17)/('P&L'!$D$5*F$5) -> 0.6763403
A9: 0.45 | B9: =(('P&L'!$D$5*B$5)-(('P&L'!$D$5*B$5)*(Funnels!$D$25*$A9+Funnels!$D$24*Assumptions!$E$58))-'P&L'!$D$17)/('P&L'!$D$5*B$5) -> 0.61112331 | C9: =(('P&L'!$D$5*C$5)-(('P&L'!$D$5*C$5)*(Funnels!$D$25*$A9+Funnels!$D$24*Assumptions!$E$58))-'P&L'!$D$17)/('P&L'!$D$5*C$5) -> 0.63245304 | D9: =(('P&L'!$D$5*D$5)-(('P&L'!$D$5*D$5)*(Funnels!$D$25*$A9+Funnels!$D$24*Assumptions!$E$58))-'P&L'!$D$17)/('P&L'!$D$5*D$5) -> 0.64738385 | E9: =(('P&L'!$D$5*E$5)-(('P&L'!$D$5*E$5)*(Funnels!$D$25*$A9+Funnels!$D$24*Assumptions!$E$58))-'P&L'!$D$17)/('P&L'!$D$5*E$5) -> 0.65841966 | F9: =(('P&L'!$D$5*F$5)-(('P&L'!$D$5*F$5)*(Funnels!$D$25*$A9+Funnels!$D$24*Assumptions!$E$58))-'P&L'!$D$17)/('P&L'!$D$5*F$5) -> 0.66690875
A10: 0.5 | B10: =(('P&L'!$D$5*B$5)-(('P&L'!$D$5*B$5)*(Funnels!$D$25*$A10+Funnels!$D$24*Assumptions!$E$58))-'P&L'!$D$17)/('P&L'!$D$5*B$5) -> 0.59540407 | C10: =(('P&L'!$D$5*C$5)-(('P&L'!$D$5*C$5)*(Funnels!$D$25*$A10+Funnels!$D$24*Assumptions!$E$58))-'P&L'!$D$17)/('P&L'!$D$5*C$5) -> 0.61673379 | D10: =(('P&L'!$D$5*D$5)-(('P&L'!$D$5*D$5)*(Funnels!$D$25*$A10+Funnels!$D$24*Assumptions!$E$58))-'P&L'!$D$17)/('P&L'!$D$5*D$5) -> 0.6316646 | E10: =(('P&L'!$D$5*E$5)-(('P&L'!$D$5*E$5)*(Funnels!$D$25*$A10+Funnels!$D$24*Assumptions!$E$58))-'P&L'!$D$17)/('P&L'!$D$5*E$5) -> 0.64270042 | F10: =(('P&L'!$D$5*F$5)-(('P&L'!$D$5*F$5)*(Funnels!$D$25*$A10+Funnels!$D$24*Assumptions!$E$58))-'P&L'!$D$17)/('P&L'!$D$5*F$5) -> 0.6511895
A11: 0.55 | B11: =(('P&L'!$D$5*B$5)-(('P&L'!$D$5*B$5)*(Funnels!$D$25*$A11+Funnels!$D$24*Assumptions!$E$58))-'P&L'!$D$17)/('P&L'!$D$5*B$5) -> 0.57968483 | C11: =(('P&L'!$D$5*C$5)-(('P&L'!$D$5*C$5)*(Funnels!$D$25*$A11+Funnels!$D$24*Assumptions!$E$58))-'P&L'!$D$17)/('P&L'!$D$5*C$5) -> 0.60101455 | D11: =(('P&L'!$D$5*D$5)-(('P&L'!$D$5*D$5)*(Funnels!$D$25*$A11+Funnels!$D$24*Assumptions!$E$58))-'P&L'!$D$17)/('P&L'!$D$5*D$5) -> 0.61594536 | E11: =(('P&L'!$D$5*E$5)-(('P&L'!$D$5*E$5)*(Funnels!$D$25*$A11+Funnels!$D$24*Assumptions!$E$58))-'P&L'!$D$17)/('P&L'!$D$5*E$5) -> 0.62698117 | F11: =(('P&L'!$D$5*F$5)-(('P&L'!$D$5*F$5)*(Funnels!$D$25*$A11+Funnels!$D$24*Assumptions!$E$58))-'P&L'!$D$17)/('P&L'!$D$5*F$5) -> 0.63547026
A13: WHAT VYNE CAN AFFORD (Year 3)
A14: Max blended commission rate at 25% EBITDA margin | B14: =1-0.25-'P&L'!$D$17/'P&L'!$D$5 -> 0.66539209
A15: Max blended commission rate at 30% EBITDA margin | B15: =1-0.3-'P&L'!$D$17/'P&L'!$D$5 -> 0.61539209
A16: Modeled blended commission rate (Year 3) | B16: ='P&L'!$D$10 -> 0.2585767
A17: Headroom vs. 25% margin ceiling | B17: =B14-B16 -> 0.40681539
A19: Read: if headroom is positive, the recommended tier structure on the Recruiters tab is affordable at target margin. If negative, reduce Tier rates or raise VYNE-lead mix before extending offers.

Sheet Commission Stress Test
A1: Commission Plan Stress Test — Options A / B / C vs. Base Model (Year 3 basis)
A3: TIER SCHEDULES — marginal rates on Annual Verified T12 Revenue Hired; % of collected VYNE fee
A4: Tier | B4: A — Recruiter-gen | C4: A — VYNE-gen | D4: B — Recruiter-gen | E4: B — VYNE-gen | F4: C — Recruiter-gen | G4: C — VYNE-gen
A5: Tier 1: first $5M T12 hired | B5: 0.55 | C5: 0.45 | D5: 0.45 | E5: 0.28 | F5: 0.6 | G5: 0.45
A6: Tier 2: $5M – $10M | B6: 0.6 | C6: 0.5 | D6: 0.5 | E6: 0.32 | F6: 0.65 | G6: 0.5
A7: Tier 3: $10M – $20M | B7: 0.65 | C7: 0.55 | D7: 0.55 | E7: 0.36 | F7: 0.7 | G7: 0.55
A8: Tier 4: above $20M | B8: 0.7 | C8: 0.6 | D8: 0.6 | E8: 0.4 | F8: 0.75 | G8: 0.6
A9: Tier breakpoints ($mm) | B9: 5 | C9: 10 | D9: 20
A11: MATURE RECRUITER BOOK (Year 3, Expected productivity)
A12: Annual Verified T12 Revenue Hired per recruiter ($mm) | B12: =Funnels!D18*(Revenue!D13/Revenue!D5) -> 10.89648
A13: VYNE fee generated per recruiter | B13: =Funnels!D18*Revenue!D19 -> 996912
A14: T12 in Tier 1 ($mm) | B14: =MIN(B12,B9) -> 5
A15: T12 in Tier 2 ($mm) | B15: =MAX(0,MIN(B12,C9)-B9) -> 5
A16: T12 in Tier 3 ($mm) | B16: =MAX(0,MIN(B12,D9)-C9) -> 0.89648
A17: T12 in Tier 4 ($mm) | B17: =MAX(0,B12-D9) -> 0
A18: Blended payout rate at this book size | B18: =($B$14*B5+$B$15*B6+$B$16*B7+$B$17*B8)/$B$12 -> 0.58117043 | C18: =($B$14*C5+$B$15*C6+$B$16*C7+$B$17*C8)/$B$12 -> 0.48117043 | D18: =($B$14*D5+$B$15*D6+$B$16*D7+$B$17*D8)/$B$12 -> 0.48117043 | E18: =($B$14*E5+$B$15*E6+$B$16*E7+$B$17*E8)/$B$12 -> 0.30493635 | F18: =($B$14*F5+$B$15*F6+$B$16*F7+$B$17*F8)/$B$12 -> 0.63117043 | G18: =($B$14*G5+$B$15*G6+$B$16*G7+$B$17*G8)/$B$12 -> 0.48117043
A20: HEAD-TO-HEAD — YEAR 3
B21: BASE MODEL | C21: OPTION A | D21: OPTION B | E21: OPTION C
A22: Blended payout — recruiter-sourced | B22: =Assumptions!$E$57 -> 0.42 | C22: =$B$18 -> 0.58117043 | D22: =$D$18 -> 0.48117043 | E22: =$F$18 -> 0.63117043
A23: Blended payout — VYNE-generated | B23: =Assumptions!$E$58 -> 0.27 | C23: =$C$18 -> 0.48117043 | D23: =$E$18 -> 0.30493635 | E23: =$G$18 -> 0.48117043
A24: Recruiter commission (own-sourced book) | B24: =$B$13*B22 -> 418703.04 | C24: =$B$13*C22 -> 579375.78 | D24: =$B$13*D22 -> 479684.58 | E24: =$B$13*E22 -> 629221.38
A25: RECRUITER EARNINGS (all commission, 1099) | B25: =B24 -> 418703.04 | C25: =C24 -> 579375.78 | D25: =D24 -> 479684.58 | E25: =E24 -> 629221.38
A26: VYNE net contribution per recruiter | B26: =$B$13-B24 -> 578208.96 | C26: =$B$13-C24 -> 417536.22 | D26: =$B$13-D24 -> 517227.42 | E26: =$B$13-E24 -> 367690.62
A27: Contribution margin on recruiter revenue | B27: =B26/$B$13 -> 0.58 | C27: =C26/$B$13 -> 0.41882957 | D27: =D26/$B$13 -> 0.51882957 | E27: =E26/$B$13 -> 0.36882957
A29: Revenue (Year 3, unchanged) | B29: =Revenue!$D$18 -> 4756488 | C29: =Revenue!$D$18 -> 4756488 | D29: =Revenue!$D$18 -> 4756488 | E29: =Revenue!$D$18 -> 4756488
A30: Commission expense | B30: ='P&L'!$D$9 -> 1229917 | C30: =Revenue!$D$22*C23+Revenue!$D$23*C22 -> 1941650.3 | D30: =Revenue!$D$22*D23+Revenue!$D$23*D22 -> 1399266.6 | E30: =Revenue!$D$22*E23+Revenue!$D$23*E22 -> 2016418.7
A31: Firm blended commission (% of revenue) | B31: =B30/B29 -> 0.2585767 | C31: =C30/C29 -> 0.40821091 | D31: =D30/D29 -> 0.29418062 | E31: =E30/E29 -> 0.42393016
A32: Gross profit | B32: =B29-B30 -> 3526571 | C32: =C29-C30 -> 2814837.7 | D32: =D29-D30 -> 3357221.4 | E32: =E29-E30 -> 2740069.3
A33: VYNE GROSS MARGIN | B33: =B32/B29 -> 0.7414233 | C33: =C32/C29 -> 0.59178909 | D33: =D32/D29 -> 0.70581938 | E33: =E32/E29 -> 0.57606984
A34: Fixed costs (payroll + opex) | B34: ='P&L'!$D$17 -> 402436.5 | C34: ='P&L'!$D$17 -> 402436.5 | D34: ='P&L'!$D$17 -> 402436.5 | E34: ='P&L'!$D$17 -> 402436.5
A35: OPERATING PROFIT (EBITDA) | B35: =B32-B34 -> 3124134.5 | C35: =C32-C34 -> 2412401.2 | D35: =D32-D34 -> 2954784.9 | E35: =E32-E34 -> 2337632.8
A36: Operating margin | B36: =B35/B29 -> 0.65681539 | C36: =C35/C29 -> 0.50718118 | D36: =D35/D29 -> 0.62121147 | E36: =E35/E29 -> 0.49146193
A37: Clawback + reserve funding (unchanged) | B37: ='Founder & Capital'!$D$6+'Founder & Capital'!$D$7 -> 275620.81 | C37: ='Founder & Capital'!$D$6+'Founder & Capital'!$D$7 -> 275620.81 | D37: ='Founder & Capital'!$D$6+'Founder & Capital'!$D$7 -> 275620.81 | E37: ='Founder & Capital'!$D$6+'Founder & Capital'!$D$7 -> 275620.81
A38: Pre-distribution profit | B38: =B35-B37 -> 2848513.7 | C38: =C35-C37 -> 2136780.4 | D38: =D35-D37 -> 2679164.1 | E38: =E35-E37 -> 2062012
A39: Reinvestment pool | B39: =MAX(0,B38)*Assumptions!$E$71 -> 712128.43 | C39: =MAX(0,C38)*Assumptions!$E$71 -> 534195.1 | D39: =MAX(0,D38)*Assumptions!$E$71 -> 669791.03 | E39: =MAX(0,E38)*Assumptions!$E$71 -> 515503
A40: AI share of reinvestment pool | B40: 0.35 | F40: Based on AI:marketing budget ratio; adjustable
A41: AI INVESTMENT CAPACITY | B41: =B39*$B$40 -> 249244.95 | C41: =C39*$B$40 -> 186968.28 | D41: =D39*$B$40 -> 234426.86 | E41: =E39*$B$40 -> 180426.05
A42: MARKETING INVESTMENT CAPACITY | B42: =B39*(1-$B$40) -> 462883.48 | C42: =C39*(1-$B$40) -> 347226.81 | D42: =D39*(1-$B$40) -> 435364.17 | E42: =E39*(1-$B$40) -> 335076.95
A43: OWNER INCOME (salary + distributions) | B43: ='Hiring & Expenses'!$D$10+MAX(0,B38-B39) -> 2252545.3 | C43: ='Hiring & Expenses'!$D$10+MAX(0,C38-C39) -> 1718745.3 | D43: ='Hiring & Expenses'!$D$10+MAX(0,D38-D39) -> 2125533.1 | E43: ='Hiring & Expenses'!$D$10+MAX(0,E38-E39) -> 1662669
A44: BREAK-EVEN (placements/yr) | B44: =B34/(Revenue!$D$19*(1-B31)) -> 3.1557507 | C44: =C34/(Revenue!$D$19*(1-C31)) -> 3.9536841 | D44: =D34/(Revenue!$D$19*(1-D31)) -> 3.3149374 | E44: =E34/(Revenue!$D$19*(1-E31)) -> 4.0615684
...

Sheet Growth Engine
A1: VYNE Growth Engine — Reverse Funnel by Annual Verified T12 Revenue Hired Target
A3: Scenario follows the Assumptions tab switch. All conversion rates live on Assumptions (Growth Engine sections). Channel mix below is stage-specific (blue).
A5: GROWTH TARGETS
A6: Target Annual Verified T12 Revenue Hired ($mm) | B6: 10 | C6: 25 | D6: 50 | E6: 100 | F6: 250
A7: Avg verified T12 per hire ($mm) | B7: =(Assumptions!$E$18*Assumptions!$E$15+Assumptions!$E$19*Assumptions!$E$16+Assumptions!$E$20*Assumptions!$E$17) -> 1.88 | C7: =(Assumptions!$E$18*Assumptions!$E$15+Assumptions!$E$19*Assumptions!$E$16+Assumptions!$E$20*Assumptions!$E$17) -> 1.88 | D7: =(Assumptions!$E$18*Assumptions!$E$15+Assumptions!$E$19*Assumptions!$E$16+Assumptions!$E$20*Assumptions!$E$17) -> 1.88 | E7: =(Assumptions!$E$18*Assumptions!$E$15+Assumptions!$E$19*Assumptions!$E$16+Assumptions!$E$20*Assumptions!$E$17) -> 1.88 | F7: =(Assumptions!$E$18*Assumptions!$E$15+Assumptions!$E$19*Assumptions!$E$16+Assumptions!$E$20*Assumptions!$E$17) -> 1.88
A8: OFFICIAL HIRES REQUIRED | B8: =B6/B7 -> 5.3191489 | C8: =C6/C7 -> 13.297872 | D8: =D6/D7 -> 26.595745 | E8: =E6/E7 -> 53.191489 | F8: =F6/F7 -> 132.97872
A9: Implied VYNE billed revenue | B9: =B8*(Assumptions!$E$18*Assumptions!$E$15*Assumptions!$E$12+Assumptions!$E$19*Assumptions!$E$16*Assumptions!$E$13+Assumptions!$E$20*Assumptions!$E$17*Assumptions!$E$14)*1000000 -> 914893.62 | C9: =C8*(Assumptions!$E$18*Assumptions!$E$15*Assumptions!$E$12+Assumptions!$E$19*Assumptions!$E$16*Assumptions!$E$13+Assumptions!$E$20*Assumptions!$E$17*Assumptions!$E$14)*1000000 -> 2287234 | D9: =D8*(Assumptions!$E$18*Assumptions!$E$15*Assumptions!$E$12+Assumptions!$E$19*Assumptions!$E$16*Assumptions!$E$13+Assumptions!$E$20*Assumptions!$E$17*Assumptions!$E$14)*1000000 -> 4574468.1 | E9: =E8*(Assumptions!$E$18*Assumptions!$E$15*Assumptions!$E$12+Assumptions!$E$19*Assumptions!$E$16*Assumptions!$E$13+Assumptions!$E$20*Assumptions!$E$17*Assumptions!$E$14)*1000000 -> 9148936.2 | F9: =F8*(Assumptions!$E$18*Assumptions!$E$15*Assumptions!$E$12+Assumptions!$E$19*Assumptions!$E$16*Assumptions!$E$13+Assumptions!$E$20*Assumptions!$E$17*Assumptions!$E$14)*1000000 -> 22872340
A10: Share of experienced advisor moves | B10: =B8/Assumptions!$E$7 -> 0.00055991041 | C10: =C8/Assumptions!$E$7 -> 0.001399776 | D10: =D8/Assumptions!$E$7 -> 0.0027995521 | E10: =E8/Assumptions!$E$7 -> 0.0055991041 | F10: =F8/Assumptions!$E$7 -> 0.01399776
A11: CHANNEL MIX — % OF HIRES (stage-specific inputs)
A12: Inbound share of hires | B12: 0.2 | C12: 0.25 | D12: 0.3 | E12: 0.35 | F12: 0.4
A13: Outbound share of hires | B13: 0.3 | C13: 0.35 | D13: 0.35 | E13: 0.35 | F13: 0.35
A14: Referral share of hires | B14: 0.4 | C14: 0.3 | D14: 0.25 | E14: 0.2 | F14: 0.15
A15: Conference share of hires | B15: 0.1 | C15: 0.1 | D15: 0.1 | E15: 0.1 | F15: 0.1
A16: Mix check (must equal 100%) | B16: =SUM(B12:B15) -> 1 | C16: =SUM(C12:C15) -> 1 | D16: =SUM(D12:D15) -> 1 | E16: =SUM(E12:E15) -> 1 | F16: =SUM(F12:F15) -> 1
A17: INBOUND CHANNEL
A18: Official hires | B18: =B8*B$12 -> 1.0638298 | C18: =C8*C$12 -> 3.3244681 | D18: =D8*D$12 -> 7.9787234 | E18: =E8*E$12 -> 18.617021 | F18: =F8*F$12 -> 53.191489
A19: Offers required | B19: =B18/Assumptions!$E$77 -> 1.3297872 | C19: =C18/Assumptions!$E$77 -> 4.1555851 | D19: =D18/Assumptions!$E$77 -> 9.9734043 | E19: =E18/Assumptions!$E$77 -> 23.271277 | F19: =F18/Assumptions!$E$77 -> 66.489362
A20: Qualified opportunities | B20: =B19/Assumptions!$E$76 -> 2.417795 | C20: =C19/Assumptions!$E$76 -> 7.5556093 | D20: =D19/Assumptions!$E$76 -> 18.133462 | E20: =E19/Assumptions!$E$76 -> 42.311412 | F20: =F19/Assumptions!$E$76 -> 120.88975
A21: Firm introductions | B21: =B20*Assumptions!$E$99 -> 7.2533849 | C21: =C20*Assumptions!$E$99 -> 22.666828 | D21: =D20*Assumptions!$E$99 -> 54.400387 | E21: =E20*Assumptions!$E$99 -> 126.93424 | F21: =F20*Assumptions!$E$99 -> 362.66925
A22: Discovery calls | B22: =B20/Assumptions!$E$75 -> 6.0444874 | C22: =C20/Assumptions!$E$75 -> 18.889023 | D22: =D20/Assumptions!$E$75 -> 45.333656 | E22: =E20/Assumptions!$E$75 -> 105.77853 | F22: =F20/Assumptions!$E$75 -> 302.22437
A23: Leads | B23: =B22/Assumptions!$E$74 -> 17.269964 | C23: =C22/Assumptions!$E$74 -> 53.968638 | D23: =D22/Assumptions!$E$74 -> 129.52473 | E23: =E22/Assumptions!$E$74 -> 302.22437 | F23: =F22/Assumptions!$E$74 -> 863.4982
A24: Website visitors required (annual) | B24: =B23/Assumptions!$E$27 -> 1726.9964 | C24: =C23/Assumptions!$E$27 -> 5396.8638 | D24: =D23/Assumptions!$E$27 -> 12952.473 | E24: =E23/Assumptions!$E$27 -> 30222.437 | F24: =F23/Assumptions!$E$27 -> 86349.82
A25: Website visitors required (monthly) | B25: =B23/Assumptions!$E$27/12 -> 143.91637 | C25: =C23/Assumptions!$E$27/12 -> 449.73865 | D25: =D23/Assumptions!$E$27/12 -> 1079.3728 | E25: =E23/Assumptions!$E$27/12 -> 2518.5364 | F25: =F23/Assumptions!$E$27/12 -> 7195.8184
A26: OUTBOUND CHANNEL
A27: Official hires | B27: =B8*B$13 -> 1.5957447 | C27: =C8*C$13 -> 4.6542553 | D27: =D8*D$13 -> 9.3085106 | E27: =E8*E$13 -> 18.617021 | F27: =F8*F$13 -> 46.542553
A28: Offers required | B28: =B27/Assumptions!$E$83 -> 2.1276596 | C28: =C27/Assumptions!$E$83 -> 6.2056738 | D28: =D27/Assumptions!$E$83 -> 12.411348 | E28: =E27/Assumptions!$E$83 -> 24.822695 | F28: =F27/Assumptions!$E$83 -> 62.056738
A29: Qualified opportunities | B29: =B28/Assumptions!$E$82 -> 4.7281324 | C29: =C28/Assumptions!$E$82 -> 13.790386 | D29: =D28/Assumptions!$E$82 -> 27.580772 | E29: =E28/Assumptions!$E$82 -> 55.161545 | F29: =F28/Assumptions!$E$82 -> 137.90386
A30: Firm introductions | B30: =B29*Assumptions!$E$99 -> 14.184397 | C30: =C29*Assumptions!$E$99 -> 41.371158 | D30: =D29*Assumptions!$E$99 -> 82.742317 | E30: =E29*Assumptions!$E$99 -> 165.48463 | F30: =F29*Assumptions!$E$99 -> 413.71158
A31: Discovery calls | B31: =B29/Assumptions!$E$81 -> 13.50895 | C31: =C29/Assumptions!$E$81 -> 39.401103 | D31: =D29/Assumptions!$E$81 -> 78.802206 | E31: =E29/Assumptions!$E$81 -> 157.60441 | F31: =F29/Assumptions!$E$81 -> 394.01103
A32: Leads | B32: =B31/Assumptions!$E$80 -> 30.019888 | C32: =C31/Assumptions!$E$80 -> 87.558007 | D32: =D31/Assumptions!$E$80 -> 175.11601 | E32: =E31/Assumptions!$E$80 -> 350.23203 | F32: =F31/Assumptions!$E$80 -> 875.58007
A33: Live conversations required | B33: =B32/Assumptions!$E$79 -> 300.19888 | C33: =C32/Assumptions!$E$79 -> 875.58007 | D33: =D32/Assumptions!$E$79 -> 1751.1601 | E33: =E32/Assumptions!$E$79 -> 3502.3203 | F33: =F32/Assumptions!$E$79 -> 8755.8007
A34: Dials required (annual) | B34: =B32/Assumptions!$E$79/Assumptions!$E$34 -> 3752.486 | C34: =C32/Assumptions!$E$79/Assumptions!$E$34 -> 10944.751 | D34: =D32/Assumptions!$E$79/Assumptions!$E$34 -> 21889.502 | E34: =E32/Assumptions!$E$79/Assumptions!$E$34 -> 43779.004 | F34: =F32/Assumptions!$E$79/Assumptions!$E$34 -> 109447.51
A35: Unique advisors contacted | B35: =B32/Assumptions!$E$79/Assumptions!$E$34/Assumptions!$E$84 -> 625.41434 | C35: =C32/Assumptions!$E$79/Assumptions!$E$34/Assumptions!$E$84 -> 1824.1251 | D35: =D32/Assumptions!$E$79/Assumptions!$E$34/Assumptions!$E$84 -> 3648.2503 | E35: =E32/Assumptions!$E$79/Assumptions!$E$34/Assumptions!$E$84 -> 7296.5006 | F35: =F32/Assumptions!$E$79/Assumptions!$E$34/Assumptions!$E$84 -> 18241.251
A36: REFERRAL CHANNEL
A37: Official hires | B37: =B8*B$14 -> 2.1276596 | C37: =C8*C$14 -> 3.9893617 | D37: =D8*D$14 -> 6.6489362 | E37: =E8*E$14 -> 10.638298 | F37: =F8*F$14 -> 19.946809
A38: Offers required | B38: =B37/Assumptions!$E$89 -> 2.5031289 | C38: =C37/Assumptions!$E$89 -> 4.6933667 | D38: =D37/Assumptions!$E$89 -> 7.8222778 | E38: =E37/Assumptions!$E$89 -> 12.515645 | F38: =F37/Assumptions!$E$89 -> 23.466834
A39: Qualified opportunities | B39: =B38/Assumptions!$E$88 -> 3.5758984 | C39: =C38/Assumptions!$E$88 -> 6.7048096 | D39: =D38/Assumptions!$E$88 -> 11.174683 | E39: =E38/Assumptions!$E$88 -> 17.879492 | F39: =F38/Assumptions!$E$88 -> 33.524048
A40: Firm introductions | B40: =B39*Assumptions!$E$99 -> 10.727695 | C40: =C39*Assumptions!$E$99 -> 20.114429 | D40: =D39*Assumptions!$E$99 -> 33.524048 | E40: =E39*Assumptions!$E$99 -> 53.638477 | F40: =F39*Assumptions!$E$99 -> 100.57214
A41: Discovery calls | B41: =B39/Assumptions!$E$87 -> 5.5013822 | C41: =C39/Assumptions!$E$87 -> 10.315092 | D41: =D39/Assumptions!$E$87 -> 17.191819 | E41: =E39/Assumptions!$E$87 -> 27.506911 | F41: =F39/Assumptions!$E$87 -> 51.575458
A42: Leads | B42: =B41/Assumptions!$E$86 -> 7.3351763 | C42: =C41/Assumptions!$E$86 -> 13.753456 | D42: =D41/Assumptions!$E$86 -> 22.922426 | E42: =E41/Assumptions!$E$86 -> 36.675881 | F42: =F41/Assumptions!$E$86 -> 68.767278
...

Sheet Founder & Capital
A1: Founder Economics & Capital Allocation Plan
B3: Year 1 | C3: Year 2 | D3: Year 3 | E3: Year 4 | F3: Year 5
A4: CAPITAL ALLOCATION WATERFALL (priority order)
A5: EBITDA | B5: ='P&L'!B19 -> 719809.6 | C5: ='P&L'!C19 -> 1680943.3 | D5: ='P&L'!D19 -> 3124134.5 | E5: ='P&L'!E19 -> 5016712.6 | F5: ='P&L'!F19 -> 7204358.3
A6: 1) Clawback reserve funding (net) | B6: =-'Cash Flow'!B9-'Cash Flow'!B10 -> 90059.2 | C6: =-'Cash Flow'!C9-'Cash Flow'!C10 -> 136039.96 | D6: =-'Cash Flow'!D9-'Cash Flow'!D10 -> 215297.56 | E6: =-'Cash Flow'!E9-'Cash Flow'!E10 -> 287675.16 | F6: =-'Cash Flow'!F9-'Cash Flow'!F10 -> 340513.56
A7: 2) Cash reserve build (to 6-month target) | B7: ='Cash Flow'!B14 -> 119700 | C7: =MAX(0,'Cash Flow'!C14-'Cash Flow'!B14) -> 21195 | D7: =MAX(0,'Cash Flow'!D14-'Cash Flow'!C14) -> 60323.25 | E7: =MAX(0,'Cash Flow'!E14-'Cash Flow'!D14) -> 29786.888 | F7: =MAX(0,'Cash Flow'!F14-'Cash Flow'!E14) -> 26805.336
A8: Pre-distribution profit | B8: =B5-B6-B7 -> 510050.4 | C8: =C5-C6-C7 -> 1523708.3 | D8: =D5-D6-D7 -> 2848513.7 | E8: =E5-E6-E7 -> 4699250.6 | F8: =F5-F6-F7 -> 6837039.4
A9: 3) Reinvestment (AI, marketing, data) | B9: =MAX(0,B8)*Assumptions!$E$71 -> 127512.6 | C9: =MAX(0,C8)*Assumptions!$E$71 -> 380927.08 | D9: =MAX(0,D8)*Assumptions!$E$71 -> 712128.43 | E9: =MAX(0,E8)*Assumptions!$E$71 -> 1174812.6 | F9: =MAX(0,F8)*Assumptions!$E$71 -> 1709259.8
A10: 4) Founder distributions | B10: =MAX(0,B8-B9) -> 382537.8 | C10: =MAX(0,C8-C9) -> 1142781.2 | D10: =MAX(0,D8-D9) -> 2136385.3 | E10: =MAX(0,E8-E9) -> 3524437.9 | F10: =MAX(0,F8-F9) -> 5127779.5
A11: FOUNDER ECONOMICS — Mike Davies, Founder & CEO
A12: Founder salary | B12: ='Hiring & Expenses'!B10 -> 96000 | C12: ='Hiring & Expenses'!C10 -> 105600 | D12: ='Hiring & Expenses'!D10 -> 116160 | E12: ='Hiring & Expenses'!E10 -> 127776 | F12: ='Hiring & Expenses'!F10 -> 140553.6
A13: Total founder cash compensation | B13: =B12+B10 -> 478537.8 | C13: =C12+C10 -> 1248381.2 | D13: =D12+D10 -> 2252545.3 | E13: =E12+E10 -> 3652213.9 | F13: =F12+F10 -> 5268333.1
A14: Cumulative founder cash | B14: =B13 -> 478537.8 | C14: =B14+C13 -> 1726919 | D14: =C14+D13 -> 3979464.3 | E14: =D14+E13 -> 7631678.3 | F14: =E14+F13 -> 12900011
A15: Founder cash comp / capital contributed | B15: =B14/Assumptions!$E$72 -> 4.785378 | C15: =C14/Assumptions!$E$72 -> 17.26919 | D15: =D14/Assumptions!$E$72 -> 39.794643 | E15: =E14/Assumptions!$E$72 -> 76.316783 | F15: =F14/Assumptions!$E$72 -> 129.00011
